<?xml version="1.0" encoding="UTF-8"?>
<!-- Follows updated snakebot but with added inertial components-->
<robot xmlns:xacro = "http://www.ros.org/wiki/xacro" name = "full_snakebot">
    <!-- Define colors -->
    <material name = "white">
        <color rgba = "1 1 1 1"/>
    </material>
    <material name = "black">
        <color rgba = "0 0 0 1"/>
    </material>

    <!-- Define head link -->
    <link name = "head">
        <visual>
            <origin rpy = "0 1.5708 0" xyz = "0 0 0"/>
            <geometry>
                <sphere radius = "0.05"/>
            </geometry>
            <material name = "black"/>
        </visual>
    </link>

    <!-- Module 0 -->
    <!-- Module 0 links-->
    <link name = "m0_base_link">
        <visual>
            <origin rpy = "0 1.5708 0" xyz = "0 0 0"/>
            <geometry>
                <cylinder radius = "0.05" length = "0.01"/>
            </geometry>
            <material name = "white"/>
        </visual>
    </link>
    <link name = "m0_bottom_bracket">
        <visual>
            <origin rpy = "0 1.5708 0" xyz = "0 0 0"/>
            <geometry>
                <cylinder radius = "0.05" length = "0.045"/>
            </geometry>
            <material name = "white"/>
        </visual>
        <collision>
            <origin rpy = "0 1.5708 0" xyz = "0 0 0"/>
            <geometry>
                <cylinder radius = "0.05" length = "0.045"/>
            </geometry>
        </collision>
        <inertial>
            <origin rpy = "0 1.5708 0" xyz = "0 0 0"/>
            <mass value = "0.1"/>
            <inertia ixx = "0.0001" ixy = "0" ixz = "0" iyy = "0.0001" iyz = "0" izz = "0.0001"/>  
        </inertial>
    </link>
    <link name = "m0_virtual_link_zero"></link>
    <link name = "m0_virtual_link_one"></link>
    <link name = "m0_middle_bracket">
        <visual>
            <origin rpy = "0 1.5708 0" xyz = "0 0 0"/>
            <geometry>
                <cylinder radius = "0.05" length = "0.085"/>
            </geometry>
            <material name = "white"/>
        </visual>
        <collision>
            <origin rpy = "0 1.5708 0" xyz = "0 0 0"/>
            <geometry>
                <cylinder radius = "0.05" length = "0.07"/>
            </geometry>
        </collision>
        <inertial>
            <origin rpy = "0 1.5708 0" xyz = "0 0 0"/>
            <mass value = "0.1"/>
            <inertia ixx = "0.0001" ixy = "0" ixz = "0" iyy = "0.0001" iyz = "0" izz = "0.0001"/>
        </inertial>
    </link>
    <link name = "m0_virtual_link_two"></link>
    <link name = "m0_top_bracket">
        <visual>
            <origin rpy = "0 1.5708 0" xyz = "0 0 0"/>
            <geometry>
                <cylinder radius = "0.05" length = "0.055"/>
            </geometry>
            <material name = "white"/>
        </visual>
        <!-- Collision - only for the top half! -->
        <collision>
            <origin rpy = "0 1.5708 0" xyz = "0.025 0 0"/>
            <geometry>
                <cylinder radius = "0.05" length = "0.055"/>
            </geometry>
        </collision>
        <inertial>
            <origin rpy = "0 1.5708 0" xyz = "0 0 0"/>
            <mass value = "0.1"/>
            <inertia ixx = "0.0001" ixy = "0" ixz = "0" iyy = "0.0001" iyz = "0" izz = "0.0001"/>
        </inertial>
    </link>
    <link name = "m0_virtual_link_three"/>

    <!-- Module 0 joints -->
    <!-- Head to m0 connection -->
    <joint name = "head_to_base" type = "fixed">
        <parent link = "m0_base_link"/>
        <child link = "head"/>
        <origin xyz = "-0.02 0 0"/>
    </joint>
    <!-- Joint 0: prismatic -->
    <joint name = "m0_joint_zero" type = "prismatic">
        <parent link = "m0_base_link"/>
        <child link = "m0_bottom_bracket"/>
        <axis xyz = "1 0 0"/>
        <limit lower = "0" upper = "0.02" effort = "1" velocity = "0.01"/>
        <origin rpy = "0 0 0" xyz = "0 0 0"/>
        <dynamics damping = "0.0" friction = "0.01"/>
    </joint>
    <!-- Joint 1: revolute -->
    <joint name = "m0_joint_one" type = "revolute">
        <parent link = "m0_bottom_bracket"/>
        <child link = "m0_virtual_link_zero"/>
        <axis xyz = "0 0 1"/>
        <limit lower = "-0.0873" upper = "0.0873" effort = "1" velocity = "0.01"/>
    </joint>
    <!-- Joint 2: revolute -->
    <joint name = "m0_joint_two" type = "revolute">
        <parent link = "m0_virtual_link_zero"/>
        <child link = "m0_virtual_link_one"/>
        <axis xyz = "1 0 0"/>
        <limit lower = "-0.2618" upper = "0.2618" effort = "1" velocity = "0.01"/>
        <origin xyz = "0.02 0 0"/>
    </joint>
    <!-- Spring-steel to cross-joint connection -->
    <joint name = "m0_fixed_one" type = "fixed">
        <parent link = "m0_virtual_link_one"/>
        <child link = "m0_middle_bracket"/>
        <origin rpy = "0 0 0" xyz = "0.045 0 0"/>
    </joint>
    <joint name = "m0_fixed_two" type = "fixed">
        <parent link = "m0_middle_bracket"/>
        <child link = "m0_virtual_link_two"/>
        <origin rpy = "0 0 0" xyz = "0.015 0 0"/>
    </joint>
    <!-- Joint 3: revolute -->
    <joint name = "m0_joint_three" type = "revolute">
        <parent link = "m0_virtual_link_two"/>
        <child link = "m0_virtual_link_three"/>
        <axis xyz = "0 0 1"/>
        <limit lower = "-0.5236" upper = "0.5236" effort = "1" velocity = "0.01"/>
        <origin rpy = "0 0 0" xyz = "0 0 0"/>
    </joint>
    <!-- Joint 4: revolute -->
    <joint name = "m0_joint_four" type = "revolute">
        <parent link = "m0_virtual_link_three"/>
        <child link = "m0_top_bracket"/>
        <axis xyz = "0 1 0"/>
        <limit lower = "-0.5236" upper = "0.5236" effort = "1" velocity = "0.01"/>
        <origin rpy = "0 0 0" xyz = "0.055 0 0"/>
    </joint>

    <!-- Module 1 -->
    <!-- Module 1 links-->
    <link name = "m1_base_link">
        <visual>
            <origin rpy = "0 1.5708 0" xyz = "0 0 0"/>
            <geometry>
                <cylinder radius = "0.05" length = "0.01"/>
            </geometry>
            <material name = "black"/>
        </visual>
    </link>
    <link name = "m1_bottom_bracket">
        <visual>
            <origin rpy = "0 1.5708 0" xyz = "0 0 0"/>
            <geometry>
                <cylinder radius = "0.05" length = "0.045"/>
            </geometry>
            <material name = "black"/>
        </visual>
        <collision>
            <origin rpy = "0 1.5708 0" xyz = "0 0 0"/>
            <geometry>
                <cylinder radius = "0.05" length = "0.045"/>
            </geometry>
        </collision>
        <inertial>
            <origin rpy = "0 1.5708 0" xyz = "0 0 0"/>
            <mass value = "0.1"/>
            <inertia ixx = "0.0001" ixy = "0" ixz = "0" iyy = "0.0001" iyz = "0" izz = "0.0001"/>  
        </inertial>
    </link>
    <link name = "m1_virtual_link_zero"></link>
    <link name = "m1_virtual_link_one"></link>
    <link name = "m1_middle_bracket">
        <visual>
            <origin rpy = "0 1.5708 0" xyz = "0 0 0"/>
            <geometry>
                <cylinder radius = "0.05" length = "0.085"/>
            </geometry>
            <material name = "black"/>
        </visual>
        <collision>
            <origin rpy = "0 1.5708 0" xyz = "0 0 0"/>
            <geometry>
                <cylinder radius = "0.05" length = "0.07"/>
            </geometry>
        </collision>
        <inertial>
            <origin rpy = "0 1.5708 0" xyz = "0 0 0"/>
            <mass value = "0.1"/>
            <inertia ixx = "0.0001" ixy = "0" ixz = "0" iyy = "0.0001" iyz = "0" izz = "0.0001"/>
        </inertial>
    </link>
    <link name = "m1_virtual_link_two"></link>
    <link name = "m1_top_bracket">
        <visual>
            <origin rpy = "0 1.5708 0" xyz = "0 0 0"/>
            <geometry>
                <cylinder radius = "0.05" length = "0.055"/>
            </geometry>
            <material name = "black"/>
        </visual>
        <!-- Collision - only for the top half! -->
        <collision>
            <origin rpy = "0 1.5708 0" xyz = "0.025 0 0"/>
            <geometry>
                <cylinder radius = "0.05" length = "0.055"/>
            </geometry>
        </collision>
        <inertial>
            <origin rpy = "0 1.5708 0" xyz = "0 0 0"/>
            <mass value = "0.1"/>
            <inertia ixx = "0.0001" ixy = "0" ixz = "0" iyy = "0.0001" iyz = "0" izz = "0.0001"/>
        </inertial>
    </link>
    <link name = "m1_virtual_link_three"/>

    <!-- Module 1 joints -->
    <!-- m0 to m1 connection-->
    <joint name = "m0_to_m1" type = "fixed">
        <parent link = "m0_top_bracket"/>
        <child link = "m1_base_link"/>
        <origin xyz = "0.0275 0 0"/>
    </joint>
    <!-- Joint 0: prismatic -->
    <joint name = "m1_joint_zero" type = "prismatic">
        <parent link = "m1_base_link"/>
        <child link = "m1_bottom_bracket"/>
        <axis xyz = "1 0 0"/>
        <limit lower = "0" upper = "0.02" effort = "1" velocity = "0.01"/>
        <origin rpy = "0 0 0" xyz = "0 0 0"/>
        <dynamics damping = "0.0" friction = "0.01"/>
    </joint>
    <!-- Joint 1: revolute -->
    <joint name = "m1_joint_one" type = "revolute">
        <parent link = "m1_bottom_bracket"/>
        <child link = "m1_virtual_link_zero"/>
        <axis xyz = "0 0 1"/>
        <limit lower = "-0.0873" upper = "0.0873" effort = "1" velocity = "0.01"/>
    </joint>
    <!-- Joint 2: revolute -->
    <joint name = "m1_joint_two" type = "revolute">
        <parent link = "m1_virtual_link_zero"/>
        <child link = "m1_virtual_link_one"/>
        <axis xyz = "1 0 0"/>
        <limit lower = "-0.2618" upper = "0.2618" effort = "1" velocity = "0.01"/>
        <origin xyz = "0.02 0 0"/>
    </joint>
    <!-- Spring-steel to cross-joint connection -->
    <joint name = "m1_fixed_one" type = "fixed">
        <parent link = "m1_virtual_link_one"/>
        <child link = "m1_middle_bracket"/>
        <origin rpy = "0 0 0" xyz = "0.045 0 0"/>
    </joint>
    <joint name = "m1_fixed_two" type = "fixed">
        <parent link = "m1_middle_bracket"/>
        <child link = "m1_virtual_link_two"/>
        <origin rpy = "0 0 0" xyz = "0.015 0 0"/>
    </joint>
    <!-- Joint 3: revolute -->
    <joint name = "m1_joint_three" type = "revolute">
        <parent link = "m1_virtual_link_two"/>
        <child link = "m1_virtual_link_three"/>
        <axis xyz = "0 0 1"/>
        <limit lower = "-0.5236" upper = "0.5236" effort = "1" velocity = "0.01"/>
        <origin rpy = "0 0 0" xyz = "0 0 0"/>
    </joint>
    <!-- Joint 4: revolute -->
    <joint name = "m1_joint_four" type = "revolute">
        <parent link = "m1_virtual_link_three"/>
        <child link = "m1_top_bracket"/>
        <axis xyz = "0 1 0"/>
        <limit lower = "-0.5236" upper = "0.5236" effort = "1" velocity = "0.01"/>
        <origin rpy = "0 0 0" xyz = "0.055 0 0"/>
    </joint>

    <!-- Module 2 -->
    <!-- Module 2 links-->
    <link name = "m2_base_link">
        <visual>
            <origin rpy = "0 1.5708 0" xyz = "0 0 0"/>
            <geometry>
                <cylinder radius = "0.05" length = "0.01"/>
            </geometry>
            <material name = "white"/>
        </visual>
    </link>
    <link name = "m2_bottom_bracket">
        <visual>
            <origin rpy = "0 1.5708 0" xyz = "0 0 0"/>
            <geometry>
                <cylinder radius = "0.05" length = "0.045"/>
            </geometry>
            <material name = "white"/>
        </visual>
        <collision>
            <origin rpy = "0 1.5708 0" xyz = "0 0 0"/>
            <geometry>
                <cylinder radius = "0.05" length = "0.045"/>
            </geometry>
        </collision>
        <inertial>
            <origin rpy = "0 1.5708 0" xyz = "0 0 0"/>
            <mass value = "0.1"/>
            <inertia ixx = "0.0001" ixy = "0" ixz = "0" iyy = "0.0001" iyz = "0" izz = "0.0001"/>  
        </inertial>
    </link>
    <link name = "m2_virtual_link_zero"></link>
    <link name = "m2_virtual_link_one"></link>
    <link name = "m2_middle_bracket">
        <visual>
            <origin rpy = "0 1.5708 0" xyz = "0 0 0"/>
            <geometry>
                <cylinder radius = "0.05" length = "0.085"/>
            </geometry>
            <material name = "white"/>
        </visual>
        <collision>
            <origin rpy = "0 1.5708 0" xyz = "0 0 0"/>
            <geometry>
                <cylinder radius = "0.05" length = "0.07"/>
            </geometry>
        </collision>
        <inertial>
            <origin rpy = "0 1.5708 0" xyz = "0 0 0"/>
            <mass value = "0.1"/>
            <inertia ixx = "0.0001" ixy = "0" ixz = "0" iyy = "0.0001" iyz = "0" izz = "0.0001"/>
        </inertial>
    </link>
    <link name = "m2_virtual_link_two"></link>
    <link name = "m2_top_bracket">
        <visual>
            <origin rpy = "0 1.5708 0" xyz = "0 0 0"/>
            <geometry>
                <cylinder radius = "0.05" length = "0.055"/>
            </geometry>
            <material name = "white"/>
        </visual>
        <!-- Collision - only for the top half! -->
        <collision>
            <origin rpy = "0 1.5708 0" xyz = "0.025 0 0"/>
            <geometry>
                <cylinder radius = "0.05" length = "0.055"/>
            </geometry>
        </collision>
        <inertial>
            <origin rpy = "0 1.5708 0" xyz = "0 0 0"/>
            <mass value = "0.1"/>
            <inertia ixx = "0.0001" ixy = "0" ixz = "0" iyy = "0.0001" iyz = "0" izz = "0.0001"/>
        </inertial>
    </link>
    <link name = "m2_virtual_link_three"/>

    <!-- Module 2 joints -->
    <!-- m1 to m2 connection-->
    <joint name = "m1_to_m2" type = "fixed">
        <parent link = "m1_top_bracket"/>
        <child link = "m2_base_link"/>
        <origin xyz = "0.0275 0 0"/>
    </joint>
    <!-- Joint 0: prismatic -->
    <joint name = "m2_joint_zero" type = "prismatic">
        <parent link = "m2_base_link"/>
        <child link = "m2_bottom_bracket"/>
        <axis xyz = "1 0 0"/>
        <limit lower = "0" upper = "0.02" effort = "1" velocity = "0.01"/>
        <origin rpy = "0 0 0" xyz = "0 0 0"/>
        <dynamics damping = "0.0" friction = "0.01"/>
    </joint>
    <!-- Joint 1: revolute -->
    <joint name = "m2_joint_one" type = "revolute">
        <parent link = "m2_bottom_bracket"/>
        <child link = "m2_virtual_link_zero"/>
        <axis xyz = "0 0 1"/>
        <limit lower = "-0.0873" upper = "0.0873" effort = "1" velocity = "0.01"/>
    </joint>
    <!-- Joint 2: revolute -->
    <joint name = "m2_joint_two" type = "revolute">
        <parent link = "m2_virtual_link_zero"/>
        <child link = "m2_virtual_link_one"/>
        <axis xyz = "1 0 0"/>
        <limit lower = "-0.2618" upper = "0.2618" effort = "1" velocity = "0.01"/>
        <origin xyz = "0.02 0 0"/>
    </joint>
    <!-- Spring-steel to cross-joint connection -->
    <joint name = "m2_fixed_one" type = "fixed">
        <parent link = "m2_virtual_link_one"/>
        <child link = "m2_middle_bracket"/>
        <origin rpy = "0 0 0" xyz = "0.045 0 0"/>
    </joint>
    <joint name = "m2_fixed_two" type = "fixed">
        <parent link = "m2_middle_bracket"/>
        <child link = "m2_virtual_link_two"/>
        <origin rpy = "0 0 0" xyz = "0.015 0 0"/>
    </joint>
    <!-- Joint 3: revolute -->
    <joint name = "m2_joint_three" type = "revolute">
        <parent link = "m2_virtual_link_two"/>
        <child link = "m2_virtual_link_three"/>
        <axis xyz = "0 0 1"/>
        <limit lower = "-0.5236" upper = "0.5236" effort = "1" velocity = "0.01"/>
        <origin rpy = "0 0 0" xyz = "0 0 0"/>
    </joint>
    <!-- Joint 4: revolute -->
    <joint name = "m2_joint_four" type = "revolute">
        <parent link = "m2_virtual_link_three"/>
        <child link = "m2_top_bracket"/>
        <axis xyz = "0 1 0"/>
        <limit lower = "-0.5236" upper = "0.5236" effort = "1" velocity = "0.01"/>
        <origin rpy = "0 0 0" xyz = "0.055 0 0"/>
    </joint>

    <!-- Module 3 -->
    <!-- Module 3 links-->
    <link name = "m3_base_link">
        <visual>
            <origin rpy = "0 1.5708 0" xyz = "0 0 0"/>
            <geometry>
                <cylinder radius = "0.05" length = "0.01"/>
            </geometry>
            <material name = "black"/>
        </visual>
    </link>
    <link name = "m3_bottom_bracket">
        <visual>
            <origin rpy = "0 1.5708 0" xyz = "0 0 0"/>
            <geometry>
                <cylinder radius = "0.05" length = "0.045"/>
            </geometry>
            <material name = "black"/>
        </visual>
        <collision>
            <origin rpy = "0 1.5708 0" xyz = "0 0 0"/>
            <geometry>
                <cylinder radius = "0.05" length = "0.045"/>
            </geometry>
        </collision>
        <inertial>
            <origin rpy = "0 1.5708 0" xyz = "0 0 0"/>
            <mass value = "0.1"/>
            <inertia ixx = "0.0001" ixy = "0" ixz = "0" iyy = "0.0001" iyz = "0" izz = "0.0001"/>  
        </inertial>
    </link>
    <link name = "m3_virtual_link_zero"></link>
    <link name = "m3_virtual_link_one"></link>
    <link name = "m3_middle_bracket">
        <visual>
            <origin rpy = "0 1.5708 0" xyz = "0 0 0"/>
            <geometry>
                <cylinder radius = "0.05" length = "0.085"/>
            </geometry>
            <material name = "black"/>
        </visual>
        <collision>
            <origin rpy = "0 1.5708 0" xyz = "0 0 0"/>
            <geometry>
                <cylinder radius = "0.05" length = "0.07"/>
            </geometry>
        </collision>
        <inertial>
            <origin rpy = "0 1.5708 0" xyz = "0 0 0"/>
            <mass value = "0.1"/>
            <inertia ixx = "0.0001" ixy = "0" ixz = "0" iyy = "0.0001" iyz = "0" izz = "0.0001"/>
        </inertial>
    </link>
    <link name = "m3_virtual_link_two"></link>
    <link name = "m3_top_bracket">
        <visual>
            <origin rpy = "0 1.5708 0" xyz = "0 0 0"/>
            <geometry>
                <cylinder radius = "0.05" length = "0.055"/>
            </geometry>
            <material name = "black"/>
        </visual>
        <!-- Collision - only for the top half! -->
        <collision>
            <origin rpy = "0 1.5708 0" xyz = "0.025 0 0"/>
            <geometry>
                <cylinder radius = "0.05" length = "0.055"/>
            </geometry>
        </collision>
        <inertial>
            <origin rpy = "0 1.5708 0" xyz = "0 0 0"/>
            <mass value = "0.1"/>
            <inertia ixx = "0.0001" ixy = "0" ixz = "0" iyy = "0.0001" iyz = "0" izz = "0.0001"/>
        </inertial>
    </link>
    <link name = "m3_virtual_link_three"/>

    <!-- Module 3 joints -->
    <!-- m2 to m3 connection-->
    <joint name = "m2_to_m3" type = "fixed">
        <parent link = "m2_top_bracket"/>
        <child link = "m3_base_link"/>
        <origin xyz = "0.0275 0 0"/>
    </joint>
    <!-- Joint 0: prismatic -->
    <joint name = "m3_joint_zero" type = "prismatic">
        <parent link = "m3_base_link"/>
        <child link = "m3_bottom_bracket"/>
        <axis xyz = "1 0 0"/>
        <limit lower = "0" upper = "0.02" effort = "1" velocity = "0.01"/>
        <origin rpy = "0 0 0" xyz = "0 0 0"/>
        <dynamics damping = "0.0" friction = "0.01"/>
    </joint>
    <!-- Joint 1: revolute -->
    <joint name = "m3_joint_one" type = "revolute">
        <parent link = "m3_bottom_bracket"/>
        <child link = "m3_virtual_link_zero"/>
        <axis xyz = "0 0 1"/>
        <limit lower = "-0.0873" upper = "0.0873" effort = "1" velocity = "0.01"/>
    </joint>
    <!-- Joint 2: revolute -->
    <joint name = "m3_joint_two" type = "revolute">
        <parent link = "m3_virtual_link_zero"/>
        <child link = "m3_virtual_link_one"/>
        <axis xyz = "1 0 0"/>
        <limit lower = "-0.2618" upper = "0.2618" effort = "1" velocity = "0.01"/>
        <origin xyz = "0.02 0 0"/>
    </joint>
    <!-- Spring-steel to cross-joint connection -->
    <joint name = "m3_fixed_one" type = "fixed">
        <parent link = "m3_virtual_link_one"/>
        <child link = "m3_middle_bracket"/>
        <origin rpy = "0 0 0" xyz = "0.045 0 0"/>
    </joint>
    <joint name = "m3_fixed_two" type = "fixed">
        <parent link = "m3_middle_bracket"/>
        <child link = "m3_virtual_link_two"/>
        <origin rpy = "0 0 0" xyz = "0.015 0 0"/>
    </joint>
    <!-- Joint 3: revolute -->
    <joint name = "m3_joint_three" type = "revolute">
        <parent link = "m3_virtual_link_two"/>
        <child link = "m3_virtual_link_three"/>
        <axis xyz = "0 0 1"/>
        <limit lower = "-0.5236" upper = "0.5236" effort = "1" velocity = "0.01"/>
        <origin rpy = "0 0 0" xyz = "0 0 0"/>
    </joint>
    <!-- Joint 4: revolute -->
    <joint name = "m3_joint_four" type = "revolute">
        <parent link = "m3_virtual_link_three"/>
        <child link = "m3_top_bracket"/>
        <axis xyz = "0 1 0"/>
        <limit lower = "-0.5236" upper = "0.5236" effort = "1" velocity = "0.01"/>
        <origin rpy = "0 0 0" xyz = "0.055 0 0"/>
    </joint>
    
    <!-- Define tail link -->
    <link name = "tail">
        <visual>
            <origin rpy = "0 1.5708 0" xyz = "0 0 0"/>
            <geometry>
                <cylinder radius = "0.03" length = "0.1"/>
            </geometry>
            <material name = "white"/>
        </visual>
    </link>
    <!-- m3 to tail connection -->
    <joint name = "m3_to_tail" type = "fixed">
        <parent link = "m3_top_bracket"/>
        <child link = "tail"/>
        <origin xyz = "0.0275 0 0"/>
    </joint>
</robot>